Workbook
Name final: Table2__3[]
Name Slicer_Category2: #N/A
Name Slicer_Order_Status: #N/A
Name Slicer_Payment_Method: #N/A
Name Slicer_Region: #N/A

Sheet Sheet1

Sheet Analysis sheet
B2: Discount | C2: Sum of Revenue | E2: Region | F2: Sum of Revenue | H2: Payment Method | I2: Sum of Revenue | K2: Category | L2: Average of Discount
B3: 0 | C3: 28500 | E3: East | F3: 97050 | H3: UPI | I3: 413595 | K3: Electronics | L3: 0.065
B4: 0.05 | C4: 272650 | E4: North | F4: 33720 | H4: Card | I4: 308755 | K4: Fashion | L4: 0.083333333
B5: 0.08 | C5: 207000 | E5: South | F5: 317880 | H5: Cash | I5: 36900 | K5: Home | L5: 0.02
B6: 0.1 | C6: 251100 | E6: West | F6: 310600 | H6: Grand Total | I6: 759250 | K6: Grand Total | L6: 0.05925
B7: Grand Total | C7: 759250 | E7: Grand Total | F7: 759250
B10: Top 3 products | C10: Sum of Revenue | E10: Order Status | F10: Sum of Revenue | H10: Category | I10: Sum of Revenue | K10: Row Labels | L10: Sum of Revenue
B11: Camera | C11: 207000 | E11: Cancelled | F11: 13620 | H11: Electronics | I11: 650900 | K11: Jan | L11: 265655
B12: Laptop | C12: 253000 | E12: Delivered | F12: 728830 | H12: Fashion | I12: 61700 | K12: 46023 | L12: 52250
B13: Smartphone | C13: 138750 | E13: Pending | F13: 16800 | H13: Home | I13: 46650 | K13: 46024 | L13: 45000 | T13: #VALUE!
B14: Grand Total | C14: 598750 | E14: Grand Total | F14: 759250 | H14: Grand Total | I14: 759250 | K14: 46025 | L14: 6650
K15: 46027 | L15: 7500
K16: 46029 | L16: 4320 | R16: Months | S16: Sum of Revenue
K17: 46031 | L17: 7600 | R17: Jan | S17: 265655
K18: 46033 | L18: 3600 | R18: Feb | S18: 248975
K19: 46035 | L19: 41400 | R19: Mar | S19: 244620 | T19: Top 5 Customers | U19: Sum of Revenue
K20: 46037 | L20: 5700 | R20: Grand Total | S20: 759250 | T20: Ajay | U20: 175750
K21: 46040 | L21: 3960 | T21: Arun | U21: 171200
K22: 46042 | L22: 23750 | T22: Kiran | U22: 139400
K23: 46044 | L23: 5400 | T23: David | U23: 97050
K24: 46046 | L24: 3325 | T24: Rahul | U24: 81450
K25: 46048 | L25: 49500 | T25: Grand Total | U25: 664850
K26: 46050 | L26: 5700
K27: Feb | L27: 248975
K28: 46054 | L28: 41400
K29: 46056 | L29: 5400
K30: 46058 | L30: 4750
K31: 46060 | L31: 1800
K32: 46063 | L32: 5940
K33: 46065 | L33: 52250
K34: 46068 | L34: 22500
K35: 46071 | L35: 9975
K36: 46073 | L36: 15200
K37: 46075 | L37: 3000
K38: 46078 | L38: 82800
K39: 46080 | L39: 3960
K40: Mar | L40: 244620
K41: 46082 | L41: 9500
K42: 46084 | L42: 3600
K43: 46086 | L43: 3240
...

Sheet Table2 
A1: Order_ID | B1: Order_Date | C1: Customer | D1: City | E1: Region | F1: Category | G1: Product | H1: Quantity | I1: Unit_Price | J1: Discount | K1: Payment_Method | L1: Order_Status | M1: Revenue | N1: high or low | O1: P or N | P1: A or N | Q1: Month | R1: Month_number | S1: year | T1: gross_sales
A2: ORD1001 | B2: 46023 | C2: Ajay | D2: Chennai | E2: South | F2: Electronics | G2: Laptop | H2: 1 | I2: 55000 | J2: 0.05 | K2: UPI | L2: Delivered | M2: 52250 | N2: high | O2: priority | P2: normal | Q2: January | R2: 1 | S2: 2026 | T2: 55000
A3: ORD1002 | B3: 46024 | C3: Rahul | D3: Bangalore | E3: South | F3: Electronics | G3: Smartphone | H3: 2 | I3: 25000 | J3: 0.1 | K3: Card | L3: Delivered | M3: 45000 | N3: high | O3: priority | P3: normal | Q3: January | R3: 1 | S3: 2026 | T3: 50000
A4: ORD1003 | B4: 46025 | C4: Priya | D4: Hyderabad | E4: South | F4: Fashion | G4: Shoes | H4: 2 | I4: 3500 | J4: 0.05 | K4: UPI | L4: Delivered | M4: 6650 | N4: low | O4: normal | P4: normal | Q4: January | R4: 1 | S4: 2026 | T4: 7000
A5: ORD1004 | B5: 46027 | C5: Arun | D5: Mumbai | E5: West | F5: Electronics | G5: Headphones | H5: 3 | I5: 2500 | J5: 0 | K5: Cash | L5: Delivered | M5: 7500 | N5: low | O5: normal | P5: normal | Q5: January | R5: 1 | S5: 2026 | T5: 7500
A6: ORD1006 | B6: 46031 | C6: Kiran | D6: Pune | E6: West | F6: Electronics | G6: Watch | H6: 1 | I6: 8000 | J6: 0.05 | K6: UPI | L6: Delivered | M6: 7600 | N6: low | O6: normal | P6: normal | Q6: January | R6: 1 | S6: 2026 | T6: 8000
A7: ORD1007 | B7: 46033 | C7: Anjali | D7: Chennai | E7: South | F7: Home | G7: Backpack | H7: 2 | I7: 1800 | J7: 0 | K7: UPI | L7: Delivered | M7: 3600 | N7: low | O7: normal | P7: normal | Q7: January | R7: 1 | S7: 2026 | T7: 3600
A8: ORD1008 | B8: 46035 | C8: David | D8: Kolkata | E8: East | F8: Electronics | G8: Camera | H8: 1 | I8: 45000 | J8: 0.08 | K8: Card | L8: Delivered | M8: 41400 | N8: high | O8: priority | P8: normal | Q8: January | R8: 1 | S8: 2026 | T8: 45000
A9: ORD1010 | B9: 46040 | C9: Neha | D9: Delhi | E9: North | F9: Fashion | G9: Jeans | H9: 2 | I9: 2200 | J9: 0.1 | K9: Cash | L9: Delivered | M9: 3960 | N9: low | O9: normal | P9: normal | Q9: January | R9: 1 | S9: 2026 | T9: 4400
A10: ORD1011 | B10: 46042 | C10: Ajay | D10: Chennai | E10: South | F10: Electronics | G10: Smartphone | H10: 1 | I10: 25000 | J10: 0.05 | K10: Card | L10: Delivered | M10: 23750 | N10: high | O10: priority | P10: normal | Q10: January | R10: 1 | S10: 2026 | T10: 25000
A11: ORD1012 | B11: 46044 | C11: Rahul | D11: Bangalore | E11: South | F11: Home | G11: Backpack | H11: 3 | I11: 1800 | J11: 0 | K11: UPI | L11: Delivered | M11: 5400 | N11: low | O11: normal | P11: normal | Q11: January | R11: 1 | S11: 2026 | T11: 5400
A12: ORD1013 | B12: 46046 | C12: Priya | D12: Hyderabad | E12: South | F12: Fashion | G12: Shoes | H12: 1 | I12: 3500 | J12: 0.05 | K12: Card | L12: Delivered | M12: 3325 | N12: low | O12: normal | P12: normal | Q12: January | R12: 1 | S12: 2026 | T12: 3500
A13: ORD1014 | B13: 46048 | C13: Arun | D13: Mumbai | E13: West | F13: Electronics | G13: Laptop | H13: 1 | I13: 55000 | J13: 0.1 | K13: UPI | L13: Delivered | M13: 49500 | N13: high | O13: priority | P13: normal | Q13: January | R13: 1 | S13: 2026 | T13: 55000
... A34: ORD1040 | B34: 46111 | C34: Neha | D34: Delhi | E34: North | F34: Fashion | G34: Jeans | H34: 2 | I34: 2200 | J34: 0.1 | K34: Cash | L34: Delivered | M34: 3960 | N34: low | O34: normal | P34: normal | Q34: March | R34: 3 | S34: 2026 | T34: 4400

Sheet Orders
A1: Order_ID | B1: Order_Date | C1: Customer | D1: City | E1: Region | F1: Category | G1: Product | H1: Quantity | I1: Unit_Price | J1: Discount | K1: Payment_Method | L1: Order_Status | M1: Revenue | N1: high or low | O1: P or N | P1: A or N | Q1: Month | R1: Month_number | S1: year
A2: ORD1001 | B2: 46023 | C2: Ajay | D2: Chennai | E2: South | F2: Electronics | G2: Laptop | H2: 1 | I2: 55000 | J2: 0.05 | K2: UPI | L2: Delivered | M2: =H2*I2*(1-J2) -> 52250 | N2: =IF(M2>=20000,"high","low") -> high | O2: =IF(AND(M2>=20000,L2="delivered"),"priority","normal") -> priority | P2: =IF(OR(L2="cancelled",L2="pending"),"attention","normal") -> normal | Q2: =TEXT(B2,"mmmm") -> January | R2: =MONTH(B2) -> 1 | S2: =YEAR(B2) -> 2026
A3: ORD1002 | B3: 46024 | C3: Rahul | D3: Bangalore | E3: South | F3: Electronics | G3: Smartphone | H3: 2 | I3: 25000 | J3: 0.1 | K3: Card | L3: Delivered | M3: =H3*I3*(1-J3) -> 45000 | N3: =IF(M3>=20000,"high","low") -> high | O3: =IF(AND(M3>=20000,L3="delivered"),"priority","normal") -> priority | P3: =IF(OR(L3="cancelled",L3="pending"),"attention","normal") -> normal | Q3: =TEXT(B3,"mmmm") -> January | R3: =MONTH(B3) -> 1 | S3: =YEAR(B3) -> 2026
A4: ORD1003 | B4: 46025 | C4: Priya | D4: Hyderabad | E4: South | F4: Fashion | G4: Shoes | H4: 2 | I4: 3500 | J4: 0.05 | K4: UPI | L4: Delivered | M4: =H4*I4*(1-J4) -> 6650 | N4: =IF(M4>=20000,"high","low") -> low | O4: =IF(AND(M4>=20000,L4="delivered"),"priority","normal") -> normal | P4: =IF(OR(L4="cancelled",L4="pending"),"attention","normal") -> normal | Q4: =TEXT(B4,"mmmm") -> January | R4: =MONTH(B4) -> 1 | S4: =YEAR(B4) -> 2026
A5: ORD1004 | B5: 46027 | C5: Arun | D5: Mumbai | E5: West | F5: Electronics | G5: Headphones | H5: 3 | I5: 2500 | J5: 0 | K5: Cash | L5: Delivered | M5: =H5*I5*(1-J5) -> 7500 | N5: =IF(M5>=20000,"high","low") -> low | O5: =IF(AND(M5>=20000,L5="delivered"),"priority","normal") -> normal | P5: =IF(OR(L5="cancelled",L5="pending"),"attention","normal") -> normal | Q5: =TEXT(B5,"mmmm") -> January | R5: =MONTH(B5) -> 1 | S5: =YEAR(B5) -> 2026
A6: ORD1005 | B6: 46029 | C6: Sneha | D6: Delhi | E6: North | F6: Fashion | G6: T-Shirt | H6: 4 | I6: 1200 | J6: 0.1 | K6: Card | L6: Cancelled | M6: =H6*I6*(1-J6) -> 4320 | N6: =IF(M6>=20000,"high","low") -> low | O6: =IF(AND(M6>=20000,L6="delivered"),"priority","normal") -> normal | P6: =IF(OR(L6="cancelled",L6="pending"),"attention","normal") -> attention | Q6: =TEXT(B6,"mmmm") -> January | R6: =MONTH(B6) -> 1 | S6: =YEAR(B6) -> 2026
A7: ORD1006 | B7: 46031 | C7: Kiran | D7: Pune | E7: West | F7: Electronics | G7: Watch | H7: 1 | I7: 8000 | J7: 0.05 | K7: UPI | L7: Delivered | M7: =H7*I7*(1-J7) -> 7600 | N7: =IF(M7>=20000,"high","low") -> low | O7: =IF(AND(M7>=20000,L7="delivered"),"priority","normal") -> normal | P7: =IF(OR(L7="cancelled",L7="pending"),"attention","normal") -> normal | Q7: =TEXT(B7,"mmmm") -> January | R7: =MONTH(B7) -> 1 | S7: =YEAR(B7) -> 2026
A8: ORD1007 | B8: 46033 | C8: Anjali | D8: Chennai | E8: South | F8: Home | G8: Backpack | H8: 2 | I8: 1800 | J8: 0 | K8: UPI | L8: Delivered | M8: =H8*I8*(1-J8) -> 3600 | N8: =IF(M8>=20000,"high","low") -> low | O8: =IF(AND(M8>=20000,L8="delivered"),"priority","normal") -> normal | P8: =IF(OR(L8="cancelled",L8="pending"),"attention","normal") -> normal | Q8: =TEXT(B8,"mmmm") -> January | R8: =MONTH(B8) -> 1 | S8: =YEAR(B8) -> 2026
A9: ORD1008 | B9: 46035 | C9: David | D9: Kolkata | E9: East | F9: Electronics | G9: Camera | H9: 1 | I9: 45000 | J9: 0.08 | K9: Card | L9: Delivered | M9: =H9*I9*(1-J9) -> 41400 | N9: =IF(M9>=20000,"high","low") -> high | O9: =IF(AND(M9>=20000,L9="delivered"),"priority","normal") -> priority | P9: =IF(OR(L9="cancelled",L9="pending"),"attention","normal") -> normal | Q9: =TEXT(B9,"mmmm") -> January | R9: =MONTH(B9) -> 1 | S9: =YEAR(B9) -> 2026
A10: ORD1009 | B10: 46037 | C10: Ravi | D10: Bangalore | E10: South | F10: Home | G10: Keyboard | H10: 2 | I10: 3000 | J10: 0.05 | K10: UPI | L10: Pending | M10: =H10*I10*(1-J10) -> 5700 | N10: =IF(M10>=20000,"high","low") -> low | O10: =IF(AND(M10>=20000,L10="delivered"),"priority","normal") -> normal | P10: =IF(OR(L10="cancelled",L10="pending"),"attention","normal") -> attention | Q10: =TEXT(B10,"mmmm") -> January | R10: =MONTH(B10) -> 1 | S10: =YEAR(B10) -> 2026
A11: ORD1010 | B11: 46040 | C11: Neha | D11: Delhi | E11: North | F11: Fashion | G11: Jeans | H11: 2 | I11: 2200 | J11: 0.1 | K11: Cash | L11: Delivered | M11: =H11*I11*(1-J11) -> 3960 | N11: =IF(M11>=20000,"high","low") -> low | O11: =IF(AND(M11>=20000,L11="delivered"),"priority","normal") -> normal | P11: =IF(OR(L11="cancelled",L11="pending"),"attention","normal") -> normal | Q11: =TEXT(B11,"mmmm") -> January | R11: =MONTH(B11) -> 1 | S11: =YEAR(B11) -> 2026
A12: ORD1011 | B12: 46042 | C12: Ajay | D12: Chennai | E12: South | F12: Electronics | G12: Smartphone | H12: 1 | I12: 25000 | J12: 0.05 | K12: Card | L12: Delivered | M12: =H12*I12*(1-J12) -> 23750 | N12: =IF(M12>=20000,"high","low") -> high | O12: =IF(AND(M12>=20000,L12="delivered"),"priority","normal") -> priority | P12: =IF(OR(L12="cancelled",L12="pending"),"attention","normal") -> normal | Q12: =TEXT(B12,"mmmm") -> January | R12: =MONTH(B12) -> 1 | S12: =YEAR(B12) -> 2026
A13: ORD1012 | B13: 46044 | C13: Rahul | D13: Bangalore | E13: South | F13: Home | G13: Backpack | H13: 3 | I13: 1800 | J13: 0 | K13: UPI | L13: Delivered | M13: =H13*I13*(1-J13) -> 5400 | N13: =IF(M13>=20000,"high","low") -> low | O13: =IF(AND(M13>=20000,L13="delivered"),"priority","normal") -> normal | P13: =IF(OR(L13="cancelled",L13="pending"),"attention","normal") -> normal | Q13: =TEXT(B13,"mmmm") -> January | R13: =MONTH(B13) -> 1 | S13: =YEAR(B13) -> 2026
... A41: ORD1040 | B41: 46111 | C41: Neha | D41: Delhi | E41: North | F41: Fashion | G41: Jeans | H41: 2 | I41: 2200 | J41: 0.1 | K41: Cash | L41: Delivered | M41: =H41*I41*(1-J41) -> 3960 | N41: =IF(M41>=20000,"high","low") -> low | O41: =IF(AND(M41>=20000,L41="delivered"),"priority","normal") -> normal | P41: =IF(OR(L41="cancelled",L41="pending"),"attention","normal") -> normal | Q41: =TEXT(B41,"mmmm") -> March | R41: =MONTH(B41) -> 3 | S41: =YEAR(B41) -> 2026

Sheet Analysis
A1: Totalv Quantity | B1: =SUM(Orders!H1:H41) -> 82 | M1: month | N1: revenue | P1: order_id | Q1: customer | R1: revenue | S1: product | T1: city
A2: Total sales before discount | B2: =SUMPRODUCT(Orders!H1:H41,Orders!I1:I41) -> 819500 | D2: =COUNTIF(Orders!N2:N41,"high") -> 12 | M2: january | N2: =SUMIF(Orders!Q2:Q41,"january",Orders!M2:M51) -> 265655 | P2: ord1005 | Q2: =_xlfn.XLOOKUP("ord1005",Orders!A2:A41,Orders!C2:C41) -> Sneha | R2: =_xlfn.XLOOKUP("ord1005",Orders!A2:A41,Orders!M2:M41) -> 4320 | S2: =_xlfn.XLOOKUP("ord1005",Orders!A2:A41,Orders!G2:G41) -> T-Shirt | T2: =_xlfn.XLOOKUP("ord1005",Orders!A2:A41,Orders!D2:D41) -> Delhi
A3: Average unit price | B3: =AVERAGE(Orders!I1:I41) -> 14577.5 | D3: =COUNTIF(Orders!N2:N41,"low") -> 28 | M3: february | N3: =SUMIF(Orders!Q3:Q42,"january",Orders!M3:M52) -> 213405 | P3: ord1012 | Q3: =_xlfn.XLOOKUP("ord1012",Orders!A3:A42,Orders!C3:C42) -> Rahul | R3: =_xlfn.XLOOKUP("ord1012",Orders!A3:A42,Orders!M3:M42) -> 5400 | S3: =_xlfn.XLOOKUP("ord1012",Orders!A3:A42,Orders!G3:G42) -> Backpack | T3: =_xlfn.XLOOKUP("ord1012",Orders!A3:A42,Orders!D3:D42) -> Bangalore
A4: highest unit price | B4: =MAX(Orders!I1:I41) -> 55000 | M4: march | N4: =SUMIF(Orders!Q4:Q43,"january",Orders!M4:M53) -> 168405
A5: lowest unit price | B5: =MIN(Orders!I1:I41) -> 1200 | P5: order_id | Q5: customer | R5: revenue
A6: number of orders | B6: =COUNTA(Orders!A1:A41) -> 41 | P6: ord1015 | Q6: =INDEX(Orders!C2:C41,MATCH("ord1015",Orders!A2:A41,0)) -> Sneha | R6: =INDEX(Orders!M2:M41,MATCH("ord1015",Orders!A2:A41,0)) -> 5700
A7: Acutal revenue after discount | B7: =Orders!H2*Orders!I2*(1-Orders!J2) -> 52250
A8: Total revenue after discount | B8: =SUM(Orders!M2:M41) -> 759250 | S8: =SUM(Table2[Revenue]) -> 759250
P9: =RIGHT(ORD1015,4)
A10: category | B10: revenue | C10: number of orders | D10: south revenue | E10: north revenue | F10: average revenue | G10: south count | H10: city orders | I10: city orders2 | J10: conditions | K10: priority or normal
A11: Electronics | B11: =SUMIF(Orders!F2:F41,"Electronics",Orders!M2:M41) -> 650900 | C11: =COUNTIF(Orders!F2:F41,"Electronics") -> 18 | D11: =SUMIFS(Orders!M2:M41,Orders!F2:F41,"electronics",Orders!E2:E41,"south") -> 243250 | E11: =SUMIFS(Orders!M2:M41,Orders!F2:F41,"Electronics",Orders!E2:E41,"north") -> 0 | F11: =AVERAGEIF(Orders!F2:F41,"electronics",Orders!M2:M41) -> 36161.111 | G11: =COUNTIFS(Orders!F2:F41,"electronics",Orders!E2:E41,"south") -> 6 | H11: =COUNTIFS(Orders!D2:D41,"chennai",Orders!L2:L41,"delivered") -> 8 | I11: =COUNTIFS(Orders!F2:F41,"electronics",Orders!D2:D41,"chennai",Orders!L2:L41,"delivered") -> 4 | J11: =IF(Orders!M2>=20000,"high","low") -> high | K11: =IF(AND(Orders!M2>=20000,Orders!L2="delivered"),"priority","normal") -> priority | Q11: =IFERROR(_xlfn.XLOOKUP("ord9999",Orders!A2:A41,Orders!C2:C41),"not found") -> not found
A12: home | B12: =SUMIF(Orders!F2:F41,"home",Orders!M2:M41) -> 46650 | C12: =COUNTIF(Orders!F2:F41,"Home") -> 10 | D12: =SUMIFS(Orders!M3:M42,Orders!F3:F42,"home",Orders!E3:E42,"south") -> 34350 | E12: =SUMIFS(Orders!M3:M42,Orders!F3:F42,"home",Orders!E3:E42,"north") -> 12300 | F12: =AVERAGEIF(Orders!F3:F42,"home",Orders!M3:M42) -> 4665 | G12: =COUNTIFS(Orders!F3:F42,"home",Orders!E3:E42,"south") -> 7 | H12: =COUNTIFS(Orders!D3:D42,"chennai",Orders!L3:L42,"delivered") -> 7 | I12: =COUNTIFS(Orders!F2:F41,"home",Orders!D2:D41,"chennai",Orders!L2:L41,"delivered") -> 1 | S12: =SUMIF(Table2[Category],"electronics",Table2[Quantity]) -> 29
A13: fashion | B13: =SUMIF(Orders!F2:F41,"fashion",Orders!M2:M41) -> 61700 | C13: =COUNTIF(Orders!F2:F41,"Fashion") -> 12 | D13: =SUMIFS(Orders!M4:M43,Orders!F4:F43,"fashion",Orders!E4:E43,"south") -> 40280 | E13: =SUMIFS(Orders!M4:M43,Orders!F4:F43,"fashion",Orders!E4:E43,"north") -> 21420 | F13: =AVERAGEIF(Orders!F4:F43,"fashion",Orders!M4:M43) -> 5141.6667 | G13: =COUNTIFS(Orders!F4:F43,"fashion",Orders!E4:E43,"south") -> 7 | H13: =COUNTIFS(Orders!D4:D43,"chennai",Orders!L4:L43,"delivered") -> 7 | I13: =COUNTIFS(Orders!F2:F41,"fashion",Orders!D2:D41,"chennai",Orders!L2:L41,"delivered") -> 3 | S13: =SUMIF(Table2[Category],"electronics",Table2[Revenue]) -> 650900

Sheet Detail1
A1: Details for Sum of Revenue
A3: Order_ID | B3: Order_Date | C3: Customer | D3: City | E3: Region | F3: Category | G3: Product | H3: Quantity | I3: Unit_Price | J3: Discount | K3: Payment_Method | L3: Order_Status | M3: Revenue | N3: high or low | O3: P or N | P3: A or N | Q3: Month | R3: Month_number | S3: year
A4: ORD1001 | B4: 46023 | C4: Ajay | D4: Chennai | E4: South | F4: Electronics | G4: Laptop | H4: 1 | I4: 55000 | J4: 0.05 | K4: UPI | L4: Delivered | M4: 52250 | N4: high | O4: priority | P4: normal | Q4: January | R4: 1 | S4: 2026
A5: ORD1002 | B5: 46024 | C5: Rahul | D5: Bangalore | E5: South | F5: Electronics | G5: Smartphone | H5: 2 | I5: 25000 | J5: 0.1 | K5: Card | L5: Delivered | M5: 45000 | N5: high | O5: priority | P5: normal | Q5: January | R5: 1 | S5: 2026
A6: ORD1004 | B6: 46027 | C6: Arun | D6: Mumbai | E6: West | F6: Electronics | G6: Headphones | H6: 3 | I6: 2500 | J6: 0 | K6: Cash | L6: Delivered | M6: 7500 | N6: low | O6: normal | P6: normal | Q6: January | R6: 1 | S6: 2026
A7: ORD1006 | B7: 46031 | C7: Kiran | D7: Pune | E7: West | F7: Electronics | G7: Watch | H7: 1 | I7: 8000 | J7: 0.05 | K7: UPI | L7: Delivered | M7: 7600 | N7: low | O7: normal | P7: normal | Q7: January | R7: 1 | S7: 2026
A8: ORD1008 | B8: 46035 | C8: David | D8: Kolkata | E8: East | F8: Electronics | G8: Camera | H8: 1 | I8: 45000 | J8: 0.08 | K8: Card | L8: Delivered | M8: 41400 | N8: high | O8: priority | P8: normal | Q8: January | R8: 1 | S8: 2026
A9: ORD1011 | B9: 46042 | C9: Ajay | D9: Chennai | E9: South | F9: Electronics | G9: Smartphone | H9: 1 | I9: 25000 | J9: 0.05 | K9: Card | L9: Delivered | M9: 23750 | N9: high | O9: priority | P9: normal | Q9: January | R9: 1 | S9: 2026
A10: ORD1014 | B10: 46048 | C10: Arun | D10: Mumbai | E10: West | F10: Electronics | G10: Laptop | H10: 1 | I10: 55000 | J10: 0.1 | K10: UPI | L10: Delivered | M10: 49500 | N10: high | O10: priority | P10: normal | Q10: January | R10: 1 | S10: 2026
A11: ORD1016 | B11: 46054 | C11: Kiran | D11: Pune | E11: West | F11: Electronics | G11: Camera | H11: 1 | I11: 45000 | J11: 0.08 | K11: Card | L11: Delivered | M11: 41400 | N11: high | O11: priority | P11: normal | Q11: February | R11: 2 | S11: 2026
A12: ORD1018 | B12: 46058 | C12: David | D12: Kolkata | E12: East | F12: Electronics | G12: Headphones | H12: 2 | I12: 2500 | J12: 0.05 | K12: Card | L12: Delivered | M12: 4750 | N12: low | O12: normal | P12: normal | Q12: February | R12: 2 | S12: 2026
A13: ORD1021 | B13: 46065 | C13: Ajay | D13: Chennai | E13: South | F13: Electronics | G13: Laptop | H13: 1 | I13: 55000 | J13: 0.05 | K13: UPI | L13: Delivered | M13: 52250 | N13: high | O13: priority | P13: normal | Q13: February | R13: 2 | S13: 2026
A14: ORD1022 | B14: 46068 | C14: Rahul | D14: Bangalore | E14: South | F14: Electronics | G14: Smartphone | H14: 1 | I14: 25000 | J14: 0.1 | K14: Card | L14: Delivered | M14: 22500 | N14: high | O14: priority | P14: normal | Q14: February | R14: 2 | S14: 2026
A15: ORD1024 | B15: 46073 | C15: Arun | D15: Mumbai | E15: West | F15: Electronics | G15: Watch | H15: 2 | I15: 8000 | J15: 0.05 | K15: Card | L15: Delivered | M15: 15200 | N15: low | O15: normal | P15: normal | Q15: February | R15: 2 | S15: 2026
... A43: ORD1039 | B43: 46108 | C43: Ravi | D43: Bangalore | E43: South | F43: Home | G43: Keyboard | H43: 2 | I43: 3000 | J43: 0.05 | K43: UPI | L43: Pending | M43: 5700 | N43: low | O43: normal | P43: attention | Q43: March | R43: 3 | S43: 2026

Sheet new dashboard
D2: E-Commerce Sales Performance Dashboard
E5: KPI | F5: Total Revenue | G5: Total Quantity | H5: Total Orders | I5: Average Order Value | J5: Discount vs Revenue | K5: CORRELATION
E6: VALUE | F6: =SUM(Table2[Revenue]) -> 759250 | G6: =SUM(Table2[Quantity]) -> 82 | H6: =COUNTA(Table2[Order_ID]) -> 40 | I6: =SUM(Table2[Revenue])/COUNTA(Table2[Order_ID]) -> 18981.25 | J6: =CORREL(Table2[Discount],Table2[Revenue]) -> 0.32020318 | K6: Weak Positive
